{"statistics": {"evaluated_expectations": 15, "successful_expectations": 5, "unsuccessful_expectations": 10, "success_percent": 33.33333333333333}, "results": [{"result": {"element_count": 37, "unexpected_count": 3, "unexpected_percent": 8.108108108108109, "partial_unexpected_list": []}, "exception_info": {"raised_exception": false, "exception_message": null, "exception_traceback": null}, "success": true, "meta": {}, "expectation_config": {"expectation_type": "expect_column_values_to_not_be_null", "kwargs": {"column": "Name", "mostly": 0.9, "result_format": "SUMMARY"}, "meta": {}}}, {"result": {}, "exception_info": {"raised_exception": true, "exception_message": "KeyError: 'Type of name'", "exception_traceback": "Traceback (most recent call last):\n  File \"/Users/rexboyce/opt/anaconda3/lib/python3.7/site-packages/pandas/core/indexes/base.py\", line 2897, in get_loc\n    return self._engine.get_loc(key)\n  File \"pandas/_libs/index.pyx\", line 107, in pandas._libs.index.IndexEngine.get_loc\n  File \"pandas/_libs/index.pyx\", line 131, in pandas._libs.index.IndexEngine.get_loc\n  File \"pandas/_libs/hashtable_class_helper.pxi\", line 1607, in pandas._libs.hashtable.PyObjectHashTable.get_item\n  File \"pandas/_libs/hashtable_class_helper.pxi\", line 1614, in pandas._libs.hashtable.PyObjectHashTable.get_item\nKeyError: 'Type of name'\n\nDuring handling of the above exception, another exception occurred:\n\nTraceback (most recent call last):\n  File \"/Users/rexboyce/opt/anaconda3/lib/python3.7/site-packages/great_expectations/data_asset/data_asset.py\", line 250, in wrapper\n    return_obj = func(self, **evaluation_args)\n  File \"/Users/rexboyce/opt/anaconda3/lib/python3.7/site-packages/great_expectations/dataset/pandas_dataset.py\", line 66, in inner_wrapper\n    series = self[column]\n  File \"/Users/rexboyce/opt/anaconda3/lib/python3.7/site-packages/pandas/core/frame.py\", line 2995, in __getitem__\n    indexer = self.columns.get_loc(key)\n  File \"/Users/rexboyce/opt/anaconda3/lib/python3.7/site-packages/pandas/core/indexes/base.py\", line 2899, in get_loc\n    return self._engine.get_loc(self._maybe_cast_indexer(key))\n  File \"pandas/_libs/index.pyx\", line 107, in pandas._libs.index.IndexEngine.get_loc\n  File \"pandas/_libs/index.pyx\", line 131, in pandas._libs.index.IndexEngine.get_loc\n  File \"pandas/_libs/hashtable_class_helper.pxi\", line 1607, in pandas._libs.hashtable.PyObjectHashTable.get_item\n  File \"pandas/_libs/hashtable_class_helper.pxi\", line 1614, in pandas._libs.hashtable.PyObjectHashTable.get_item\nKeyError: 'Type of name'\n"}, "success": false, "meta": {}, "expectation_config": {"expectation_type": "expect_column_values_to_not_be_null", "kwargs": {"column": "Type of name", "mostly": 0.9, "result_format": "SUMMARY"}, "meta": {}}}, {"result": {}, "exception_info": {"raised_exception": true, "exception_message": "KeyError: 'Other names'", "exception_traceback": "Traceback (most recent call last):\n  File \"/Users/rexboyce/opt/anaconda3/lib/python3.7/site-packages/pandas/core/indexes/base.py\", line 2897, in get_loc\n    return self._engine.get_loc(key)\n  File \"pandas/_libs/index.pyx\", line 107, in pandas._libs.index.IndexEngine.get_loc\n  File \"pandas/_libs/index.pyx\", line 131, in pandas._libs.index.IndexEngine.get_loc\n  File \"pandas/_libs/hashtable_class_helper.pxi\", line 1607, in pandas._libs.hashtable.PyObjectHashTable.get_item\n  File \"pandas/_libs/hashtable_class_helper.pxi\", line 1614, in pandas._libs.hashtable.PyObjectHashTable.get_item\nKeyError: 'Other names'\n\nDuring handling of the above exception, another exception occurred:\n\nTraceback (most recent call last):\n  File \"/Users/rexboyce/opt/anaconda3/lib/python3.7/site-packages/great_expectations/data_asset/data_asset.py\", line 250, in wrapper\n    return_obj = func(self, **evaluation_args)\n  File \"/Users/rexboyce/opt/anaconda3/lib/python3.7/site-packages/great_expectations/dataset/pandas_dataset.py\", line 66, in inner_wrapper\n    series = self[column]\n  File \"/Users/rexboyce/opt/anaconda3/lib/python3.7/site-packages/pandas/core/frame.py\", line 2995, in __getitem__\n    indexer = self.columns.get_loc(key)\n  File \"/Users/rexboyce/opt/anaconda3/lib/python3.7/site-packages/pandas/core/indexes/base.py\", line 2899, in get_loc\n    return self._engine.get_loc(self._maybe_cast_indexer(key))\n  File \"pandas/_libs/index.pyx\", line 107, in pandas._libs.index.IndexEngine.get_loc\n  File \"pandas/_libs/index.pyx\", line 131, in pandas._libs.index.IndexEngine.get_loc\n  File \"pandas/_libs/hashtable_class_helper.pxi\", line 1607, in pandas._libs.hashtable.PyObjectHashTable.get_item\n  File \"pandas/_libs/hashtable_class_helper.pxi\", line 1614, in pandas._libs.hashtable.PyObjectHashTable.get_item\nKeyError: 'Other names'\n"}, "success": false, "meta": {}, "expectation_config": {"expectation_type": "expect_column_values_to_not_be_null", "kwargs": {"column": "Other names", "mostly": 0.9, "result_format": "SUMMARY"}, "meta": {}}}, {"result": {"element_count": 37, "unexpected_count": 0, "unexpected_percent": 0.0, "partial_unexpected_list": []}, "exception_info": {"raised_exception": false, "exception_message": null, "exception_traceback": null}, "success": true, "meta": {}, "expectation_config": {"expectation_type": "expect_column_values_to_not_be_null", "kwargs": {"column": "BL record ID", "mostly": 0.9, "result_format": "SUMMARY"}, "meta": {}}}, {"result": {"element_count": 37, "unexpected_count": 0, "unexpected_percent": 0.0, "partial_unexpected_list": []}, "exception_info": {"raised_exception": false, "exception_message": null, "exception_traceback": null}, "success": true, "meta": {}, "expectation_config": {"expectation_type": "expect_column_values_to_not_be_null", "kwargs": {"column": "Content type", "mostly": 0.9, "result_format": "SUMMARY"}, "meta": {}}}, {"result": {}, "exception_info": {"raised_exception": true, "exception_message": "KeyError: 'Material type'", "exception_traceback": "Traceback (most recent call last):\n  File \"/Users/rexboyce/opt/anaconda3/lib/python3.7/site-packages/pandas/core/indexes/base.py\", line 2897, in get_loc\n    return self._engine.get_loc(key)\n  File \"pandas/_libs/index.pyx\", line 107, in pandas._libs.index.IndexEngine.get_loc\n  File \"pandas/_libs/index.pyx\", line 131, in pandas._libs.index.IndexEngine.get_loc\n  File \"pandas/_libs/hashtable_class_helper.pxi\", line 1607, in pandas._libs.hashtable.PyObjectHashTable.get_item\n  File \"pandas/_libs/hashtable_class_helper.pxi\", line 1614, in pandas._libs.hashtable.PyObjectHashTable.get_item\nKeyError: 'Material type'\n\nDuring handling of the above exception, another exception occurred:\n\nTraceback (most recent call last):\n  File \"/Users/rexboyce/opt/anaconda3/lib/python3.7/site-packages/great_expectations/data_asset/data_asset.py\", line 250, in wrapper\n    return_obj = func(self, **evaluation_args)\n  File \"/Users/rexboyce/opt/anaconda3/lib/python3.7/site-packages/great_expectations/dataset/pandas_dataset.py\", line 66, in inner_wrapper\n    series = self[column]\n  File \"/Users/rexboyce/opt/anaconda3/lib/python3.7/site-packages/pandas/core/frame.py\", line 2995, in __getitem__\n    indexer = self.columns.get_loc(key)\n  File \"/Users/rexboyce/opt/anaconda3/lib/python3.7/site-packages/pandas/core/indexes/base.py\", line 2899, in get_loc\n    return self._engine.get_loc(self._maybe_cast_indexer(key))\n  File \"pandas/_libs/index.pyx\", line 107, in pandas._libs.index.IndexEngine.get_loc\n  File \"pandas/_libs/index.pyx\", line 131, in pandas._libs.index.IndexEngine.get_loc\n  File \"pandas/_libs/hashtable_class_helper.pxi\", line 1607, in pandas._libs.hashtable.PyObjectHashTable.get_item\n  File \"pandas/_libs/hashtable_class_helper.pxi\", line 1614, in pandas._libs.hashtable.PyObjectHashTable.get_item\nKeyError: 'Material type'\n"}, "success": false, "meta": {}, "expectation_config": {"expectation_type": "expect_column_values_to_not_be_null", "kwargs": {"column": "Material type", "mostly": 0.9, "result_format": "SUMMARY"}, "meta": {}}}, {"result": {}, "exception_info": {"raised_exception": true, "exception_message": "KeyError: 'BNB number'", "exception_traceback": "Traceback (most recent call last):\n  File \"/Users/rexboyce/opt/anaconda3/lib/python3.7/site-packages/pandas/core/indexes/base.py\", line 2897, in get_loc\n    return self._engine.get_loc(key)\n  File \"pandas/_libs/index.pyx\", line 107, in pandas._libs.index.IndexEngine.get_loc\n  File \"pandas/_libs/index.pyx\", line 131, in pandas._libs.index.IndexEngine.get_loc\n  File \"pandas/_libs/hashtable_class_helper.pxi\", line 1607, in pandas._libs.hashtable.PyObjectHashTable.get_item\n  File \"pandas/_libs/hashtable_class_helper.pxi\", line 1614, in pandas._libs.hashtable.PyObjectHashTable.get_item\nKeyError: 'BNB number'\n\nDuring handling of the above exception, another exception occurred:\n\nTraceback (most recent call last):\n  File \"/Users/rexboyce/opt/anaconda3/lib/python3.7/site-packages/great_expectations/data_asset/data_asset.py\", line 250, in wrapper\n    return_obj = func(self, **evaluation_args)\n  File \"/Users/rexboyce/opt/anaconda3/lib/python3.7/site-packages/great_expectations/dataset/pandas_dataset.py\", line 66, in inner_wrapper\n    series = self[column]\n  File \"/Users/rexboyce/opt/anaconda3/lib/python3.7/site-packages/pandas/core/frame.py\", line 2995, in __getitem__\n    indexer = self.columns.get_loc(key)\n  File \"/Users/rexboyce/opt/anaconda3/lib/python3.7/site-packages/pandas/core/indexes/base.py\", line 2899, in get_loc\n    return self._engine.get_loc(self._maybe_cast_indexer(key))\n  File \"pandas/_libs/index.pyx\", line 107, in pandas._libs.index.IndexEngine.get_loc\n  File \"pandas/_libs/index.pyx\", line 131, in pandas._libs.index.IndexEngine.get_loc\n  File \"pandas/_libs/hashtable_class_helper.pxi\", line 1607, in pandas._libs.hashtable.PyObjectHashTable.get_item\n  File \"pandas/_libs/hashtable_class_helper.pxi\", line 1614, in pandas._libs.hashtable.PyObjectHashTable.get_item\nKeyError: 'BNB number'\n"}, "success": false, "meta": {}, "expectation_config": {"expectation_type": "expect_column_values_to_not_be_null", "kwargs": {"column": "BNB number", "mostly": 0.9, "result_format": "SUMMARY"}, "meta": {}}}, {"result": {}, "exception_info": {"raised_exception": true, "exception_message": "KeyError: 'ISBN'", "exception_traceback": "Traceback (most recent call last):\n  File \"/Users/rexboyce/opt/anaconda3/lib/python3.7/site-packages/pandas/core/indexes/base.py\", line 2897, in get_loc\n    return self._engine.get_loc(key)\n  File \"pandas/_libs/index.pyx\", line 107, in pandas._libs.index.IndexEngine.get_loc\n  File \"pandas/_libs/index.pyx\", line 131, in pandas._libs.index.IndexEngine.get_loc\n  File \"pandas/_libs/hashtable_class_helper.pxi\", line 1607, in pandas._libs.hashtable.PyObjectHashTable.get_item\n  File \"pandas/_libs/hashtable_class_helper.pxi\", line 1614, in pandas._libs.hashtable.PyObjectHashTable.get_item\nKeyError: 'ISBN'\n\nDuring handling of the above exception, another exception occurred:\n\nTraceback (most recent call last):\n  File \"/Users/rexboyce/opt/anaconda3/lib/python3.7/site-packages/great_expectations/data_asset/data_asset.py\", line 250, in wrapper\n    return_obj = func(self, **evaluation_args)\n  File \"/Users/rexboyce/opt/anaconda3/lib/python3.7/site-packages/great_expectations/dataset/pandas_dataset.py\", line 66, in inner_wrapper\n    series = self[column]\n  File \"/Users/rexboyce/opt/anaconda3/lib/python3.7/site-packages/pandas/core/frame.py\", line 2995, in __getitem__\n    indexer = self.columns.get_loc(key)\n  File \"/Users/rexboyce/opt/anaconda3/lib/python3.7/site-packages/pandas/core/indexes/base.py\", line 2899, in get_loc\n    return self._engine.get_loc(self._maybe_cast_indexer(key))\n  File \"pandas/_libs/index.pyx\", line 107, in pandas._libs.index.IndexEngine.get_loc\n  File \"pandas/_libs/index.pyx\", line 131, in pandas._libs.index.IndexEngine.get_loc\n  File \"pandas/_libs/hashtable_class_helper.pxi\", line 1607, in pandas._libs.hashtable.PyObjectHashTable.get_item\n  File \"pandas/_libs/hashtable_class_helper.pxi\", line 1614, in pandas._libs.hashtable.PyObjectHashTable.get_item\nKeyError: 'ISBN'\n"}, "success": false, "meta": {}, "expectation_config": {"expectation_type": "expect_column_values_to_not_be_null", "kwargs": {"column": "ISBN", "mostly": 0.9, "result_format": "SUMMARY"}, "meta": {}}}, {"result": {"element_count": 37, "unexpected_count": 0, "unexpected_percent": 0.0, "partial_unexpected_list": []}, "exception_info": {"raised_exception": false, "exception_message": null, "exception_traceback": null}, "success": true, "meta": {}, "expectation_config": {"expectation_type": "expect_column_values_to_not_be_null", "kwargs": {"column": "Title", "mostly": 0.9, "result_format": "SUMMARY"}, "meta": {}}}, {"result": {}, "exception_info": {"raised_exception": true, "exception_message": "KeyError: 'Country of publication'", "exception_traceback": "Traceback (most recent call last):\n  File \"/Users/rexboyce/opt/anaconda3/lib/python3.7/site-packages/pandas/core/indexes/base.py\", line 2897, in get_loc\n    return self._engine.get_loc(key)\n  File \"pandas/_libs/index.pyx\", line 107, in pandas._libs.index.IndexEngine.get_loc\n  File \"pandas/_libs/index.pyx\", line 131, in pandas._libs.index.IndexEngine.get_loc\n  File \"pandas/_libs/hashtable_class_helper.pxi\", line 1607, in pandas._libs.hashtable.PyObjectHashTable.get_item\n  File \"pandas/_libs/hashtable_class_helper.pxi\", line 1614, in pandas._libs.hashtable.PyObjectHashTable.get_item\nKeyError: 'Country of publication'\n\nDuring handling of the above exception, another exception occurred:\n\nTraceback (most recent call last):\n  File \"/Users/rexboyce/opt/anaconda3/lib/python3.7/site-packages/great_expectations/data_asset/data_asset.py\", line 250, in wrapper\n    return_obj = func(self, **evaluation_args)\n  File \"/Users/rexboyce/opt/anaconda3/lib/python3.7/site-packages/great_expectations/dataset/pandas_dataset.py\", line 66, in inner_wrapper\n    series = self[column]\n  File \"/Users/rexboyce/opt/anaconda3/lib/python3.7/site-packages/pandas/core/frame.py\", line 2995, in __getitem__\n    indexer = self.columns.get_loc(key)\n  File \"/Users/rexboyce/opt/anaconda3/lib/python3.7/site-packages/pandas/core/indexes/base.py\", line 2899, in get_loc\n    return self._engine.get_loc(self._maybe_cast_indexer(key))\n  File \"pandas/_libs/index.pyx\", line 107, in pandas._libs.index.IndexEngine.get_loc\n  File \"pandas/_libs/index.pyx\", line 131, in pandas._libs.index.IndexEngine.get_loc\n  File \"pandas/_libs/hashtable_class_helper.pxi\", line 1607, in pandas._libs.hashtable.PyObjectHashTable.get_item\n  File \"pandas/_libs/hashtable_class_helper.pxi\", line 1614, in pandas._libs.hashtable.PyObjectHashTable.get_item\nKeyError: 'Country of publication'\n"}, "success": false, "meta": {}, "expectation_config": {"expectation_type": "expect_column_values_to_not_be_null", "kwargs": {"column": "Country of publication", "mostly": 0.9, "result_format": "SUMMARY"}, "meta": {}}}, {"result": {}, "exception_info": {"raised_exception": true, "exception_message": "KeyError: 'Place of publication'", "exception_traceback": "Traceback (most recent call last):\n  File \"/Users/rexboyce/opt/anaconda3/lib/python3.7/site-packages/pandas/core/indexes/base.py\", line 2897, in get_loc\n    return self._engine.get_loc(key)\n  File \"pandas/_libs/index.pyx\", line 107, in pandas._libs.index.IndexEngine.get_loc\n  File \"pandas/_libs/index.pyx\", line 131, in pandas._libs.index.IndexEngine.get_loc\n  File \"pandas/_libs/hashtable_class_helper.pxi\", line 1607, in pandas._libs.hashtable.PyObjectHashTable.get_item\n  File \"pandas/_libs/hashtable_class_helper.pxi\", line 1614, in pandas._libs.hashtable.PyObjectHashTable.get_item\nKeyError: 'Place of publication'\n\nDuring handling of the above exception, another exception occurred:\n\nTraceback (most recent call last):\n  File \"/Users/rexboyce/opt/anaconda3/lib/python3.7/site-packages/great_expectations/data_asset/data_asset.py\", line 250, in wrapper\n    return_obj = func(self, **evaluation_args)\n  File \"/Users/rexboyce/opt/anaconda3/lib/python3.7/site-packages/great_expectations/dataset/pandas_dataset.py\", line 66, in inner_wrapper\n    series = self[column]\n  File \"/Users/rexboyce/opt/anaconda3/lib/python3.7/site-packages/pandas/core/frame.py\", line 2995, in __getitem__\n    indexer = self.columns.get_loc(key)\n  File \"/Users/rexboyce/opt/anaconda3/lib/python3.7/site-packages/pandas/core/indexes/base.py\", line 2899, in get_loc\n    return self._engine.get_loc(self._maybe_cast_indexer(key))\n  File \"pandas/_libs/index.pyx\", line 107, in pandas._libs.index.IndexEngine.get_loc\n  File \"pandas/_libs/index.pyx\", line 131, in pandas._libs.index.IndexEngine.get_loc\n  File \"pandas/_libs/hashtable_class_helper.pxi\", line 1607, in pandas._libs.hashtable.PyObjectHashTable.get_item\n  File \"pandas/_libs/hashtable_class_helper.pxi\", line 1614, in pandas._libs.hashtable.PyObjectHashTable.get_item\nKeyError: 'Place of publication'\n"}, "success": false, "meta": {}, "expectation_config": {"expectation_type": "expect_column_values_to_not_be_null", "kwargs": {"column": "Place of publication", "mostly": 0.9, "result_format": "SUMMARY"}, "meta": {}}}, {"result": {}, "exception_info": {"raised_exception": true, "exception_message": "KeyError: 'Publisher'", "exception_traceback": "Traceback (most recent call last):\n  File \"/Users/rexboyce/opt/anaconda3/lib/python3.7/site-packages/pandas/core/indexes/base.py\", line 2897, in get_loc\n    return self._engine.get_loc(key)\n  File \"pandas/_libs/index.pyx\", line 107, in pandas._libs.index.IndexEngine.get_loc\n  File \"pandas/_libs/index.pyx\", line 131, in pandas._libs.index.IndexEngine.get_loc\n  File \"pandas/_libs/hashtable_class_helper.pxi\", line 1607, in pandas._libs.hashtable.PyObjectHashTable.get_item\n  File \"pandas/_libs/hashtable_class_helper.pxi\", line 1614, in pandas._libs.hashtable.PyObjectHashTable.get_item\nKeyError: 'Publisher'\n\nDuring handling of the above exception, another exception occurred:\n\nTraceback (most recent call last):\n  File \"/Users/rexboyce/opt/anaconda3/lib/python3.7/site-packages/great_expectations/data_asset/data_asset.py\", line 250, in wrapper\n    return_obj = func(self, **evaluation_args)\n  File \"/Users/rexboyce/opt/anaconda3/lib/python3.7/site-packages/great_expectations/dataset/pandas_dataset.py\", line 66, in inner_wrapper\n    series = self[column]\n  File \"/Users/rexboyce/opt/anaconda3/lib/python3.7/site-packages/pandas/core/frame.py\", line 2995, in __getitem__\n    indexer = self.columns.get_loc(key)\n  File \"/Users/rexboyce/opt/anaconda3/lib/python3.7/site-packages/pandas/core/indexes/base.py\", line 2899, in get_loc\n    return self._engine.get_loc(self._maybe_cast_indexer(key))\n  File \"pandas/_libs/index.pyx\", line 107, in pandas._libs.index.IndexEngine.get_loc\n  File \"pandas/_libs/index.pyx\", line 131, in pandas._libs.index.IndexEngine.get_loc\n  File \"pandas/_libs/hashtable_class_helper.pxi\", line 1607, in pandas._libs.hashtable.PyObjectHashTable.get_item\n  File \"pandas/_libs/hashtable_class_helper.pxi\", line 1614, in pandas._libs.hashtable.PyObjectHashTable.get_item\nKeyError: 'Publisher'\n"}, "success": false, "meta": {}, "expectation_config": {"expectation_type": "expect_column_values_to_not_be_null", "kwargs": {"column": "Publisher", "mostly": 0.9, "result_format": "SUMMARY"}, "meta": {}}}, {"result": {"element_count": 37, "unexpected_count": 3, "unexpected_percent": 8.108108108108109, "partial_unexpected_list": []}, "exception_info": {"raised_exception": false, "exception_message": null, "exception_traceback": null}, "success": true, "meta": {}, "expectation_config": {"expectation_type": "expect_column_values_to_not_be_null", "kwargs": {"column": "Physical description", "mostly": 0.9, "result_format": "SUMMARY"}, "meta": {}}}, {"result": {}, "exception_info": {"raised_exception": true, "exception_message": "KeyError: 'Dewey classification'", "exception_traceback": "Traceback (most recent call last):\n  File \"/Users/rexboyce/opt/anaconda3/lib/python3.7/site-packages/pandas/core/indexes/base.py\", line 2897, in get_loc\n    return self._engine.get_loc(key)\n  File \"pandas/_libs/index.pyx\", line 107, in pandas._libs.index.IndexEngine.get_loc\n  File \"pandas/_libs/index.pyx\", line 131, in pandas._libs.index.IndexEngine.get_loc\n  File \"pandas/_libs/hashtable_class_helper.pxi\", line 1607, in pandas._libs.hashtable.PyObjectHashTable.get_item\n  File \"pandas/_libs/hashtable_class_helper.pxi\", line 1614, in pandas._libs.hashtable.PyObjectHashTable.get_item\nKeyError: 'Dewey classification'\n\nDuring handling of the above exception, another exception occurred:\n\nTraceback (most recent call last):\n  File \"/Users/rexboyce/opt/anaconda3/lib/python3.7/site-packages/great_expectations/data_asset/data_asset.py\", line 250, in wrapper\n    return_obj = func(self, **evaluation_args)\n  File \"/Users/rexboyce/opt/anaconda3/lib/python3.7/site-packages/great_expectations/dataset/pandas_dataset.py\", line 66, in inner_wrapper\n    series = self[column]\n  File \"/Users/rexboyce/opt/anaconda3/lib/python3.7/site-packages/pandas/core/frame.py\", line 2995, in __getitem__\n    indexer = self.columns.get_loc(key)\n  File \"/Users/rexboyce/opt/anaconda3/lib/python3.7/site-packages/pandas/core/indexes/base.py\", line 2899, in get_loc\n    return self._engine.get_loc(self._maybe_cast_indexer(key))\n  File \"pandas/_libs/index.pyx\", line 107, in pandas._libs.index.IndexEngine.get_loc\n  File \"pandas/_libs/index.pyx\", line 131, in pandas._libs.index.IndexEngine.get_loc\n  File \"pandas/_libs/hashtable_class_helper.pxi\", line 1607, in pandas._libs.hashtable.PyObjectHashTable.get_item\n  File \"pandas/_libs/hashtable_class_helper.pxi\", line 1614, in pandas._libs.hashtable.PyObjectHashTable.get_item\nKeyError: 'Dewey classification'\n"}, "success": false, "meta": {}, "expectation_config": {"expectation_type": "expect_column_values_to_not_be_null", "kwargs": {"column": "Dewey classification", "mostly": 0.9, "result_format": "SUMMARY"}, "meta": {}}}, {"result": {}, "exception_info": {"raised_exception": true, "exception_message": "KeyError: 'Languages'", "exception_traceback": "Traceback (most recent call last):\n  File \"/Users/rexboyce/opt/anaconda3/lib/python3.7/site-packages/pandas/core/indexes/base.py\", line 2897, in get_loc\n    return self._engine.get_loc(key)\n  File \"pandas/_libs/index.pyx\", line 107, in pandas._libs.index.IndexEngine.get_loc\n  File \"pandas/_libs/index.pyx\", line 131, in pandas._libs.index.IndexEngine.get_loc\n  File \"pandas/_libs/hashtable_class_helper.pxi\", line 1607, in pandas._libs.hashtable.PyObjectHashTable.get_item\n  File \"pandas/_libs/hashtable_class_helper.pxi\", line 1614, in pandas._libs.hashtable.PyObjectHashTable.get_item\nKeyError: 'Languages'\n\nDuring handling of the above exception, another exception occurred:\n\nTraceback (most recent call last):\n  File \"/Users/rexboyce/opt/anaconda3/lib/python3.7/site-packages/great_expectations/data_asset/data_asset.py\", line 250, in wrapper\n    return_obj = func(self, **evaluation_args)\n  File \"/Users/rexboyce/opt/anaconda3/lib/python3.7/site-packages/great_expectations/dataset/pandas_dataset.py\", line 66, in inner_wrapper\n    series = self[column]\n  File \"/Users/rexboyce/opt/anaconda3/lib/python3.7/site-packages/pandas/core/frame.py\", line 2995, in __getitem__\n    indexer = self.columns.get_loc(key)\n  File \"/Users/rexboyce/opt/anaconda3/lib/python3.7/site-packages/pandas/core/indexes/base.py\", line 2899, in get_loc\n    return self._engine.get_loc(self._maybe_cast_indexer(key))\n  File \"pandas/_libs/index.pyx\", line 107, in pandas._libs.index.IndexEngine.get_loc\n  File \"pandas/_libs/index.pyx\", line 131, in pandas._libs.index.IndexEngine.get_loc\n  File \"pandas/_libs/hashtable_class_helper.pxi\", line 1607, in pandas._libs.hashtable.PyObjectHashTable.get_item\n  File \"pandas/_libs/hashtable_class_helper.pxi\", line 1614, in pandas._libs.hashtable.PyObjectHashTable.get_item\nKeyError: 'Languages'\n"}, "success": false, "meta": {}, "expectation_config": {"expectation_type": "expect_column_values_to_not_be_null", "kwargs": {"column": "Languages", "mostly": 0.9, "result_format": "SUMMARY"}, "meta": {}}}], "success": false, "evaluation_parameters": {}, "meta": {"great_expectations.__version__": "0.11.2", "expectation_suite_name": "dickens_trends_2_the_second_one", "run_id": {"run_name": "20200715T200133.682803Z", "run_time": "2020-07-15T20:01:33.682803+00:00"}, "batch_kwargs": {"datasource": "annual__dir", "path": "annual/dickens_research_data_1842.csv"}, "batch_markers": {"ge_load_time": "20200715T200133.672838Z", "pandas_data_fingerprint": "2722d39c01b50bb5a8cce635e4c303bc"}, "batch_parameters": null, "validation_time": "20200715T200133.682995Z"}}