{"statistics": {"evaluated_expectations": 13, "successful_expectations": 2, "unsuccessful_expectations": 11, "success_percent": 15.384615384615385}, "results": [{"result": {"observed_value": 44}, "exception_info": {"raised_exception": false, "exception_message": null, "exception_traceback": null}, "success": false, "meta": {}, "expectation_config": {"expectation_type": "expect_table_row_count_to_be_between", "kwargs": {"max_value": 400, "min_value": 300, "result_format": "SUMMARY"}, "meta": {}}}, {"result": {"observed_value": ["BL record ID", "BL shelfmark", "All names", "Title", "Name", "Date of creation/publication", "Edition", "Content type", "Physical description", "Series title", "Number within series", "Country of publication"], "details": {"mismatched": [{"Expected Column Position": 0, "Expected": "Name", "Found": "BL record ID"}, {"Expected Column Position": 1, "Expected": "Dates associated with name", "Found": "BL shelfmark"}, {"Expected Column Position": 2, "Expected": "Type of name", "Found": "All names"}, {"Expected Column Position": 3, "Expected": "Role", "Found": "Title"}, {"Expected Column Position": 4, "Expected": "Other names", "Found": "Name"}, {"Expected Column Position": 5, "Expected": "BL record ID", "Found": "Date of creation/publication"}, {"Expected Column Position": 6, "Expected": "Type of resource", "Found": "Edition"}, {"Expected Column Position": 8, "Expected": "Material type", "Found": "Physical description"}, {"Expected Column Position": 9, "Expected": "BNB number", "Found": "Series title"}, {"Expected Column Position": 10, "Expected": "Archival Resource Key", "Found": "Number within series"}, {"Expected Column Position": 11, "Expected": "ISBN", "Found": "Country of publication"}, {"Expected Column Position": 12, "Expected": "Title", "Found": null}, {"Expected Column Position": 13, "Expected": "Variant titles", "Found": null}, {"Expected Column Position": 14, "Expected": "Series title", "Found": null}, {"Expected Column Position": 15, "Expected": "Number within series", "Found": null}, {"Expected Column Position": 16, "Expected": "Country of publication", "Found": null}, {"Expected Column Position": 17, "Expected": "Place of publication", "Found": null}, {"Expected Column Position": 18, "Expected": "Publisher", "Found": null}, {"Expected Column Position": 19, "Expected": "Date of creation/publication", "Found": null}, {"Expected Column Position": 20, "Expected": "Edition", "Found": null}, {"Expected Column Position": 21, "Expected": "Physical description", "Found": null}, {"Expected Column Position": 22, "Expected": "Dewey classification", "Found": null}, {"Expected Column Position": 23, "Expected": "BL shelfmark", "Found": null}, {"Expected Column Position": 24, "Expected": "Topics", "Found": null}, {"Expected Column Position": 25, "Expected": "Genre", "Found": null}, {"Expected Column Position": 26, "Expected": "Languages", "Found": null}, {"Expected Column Position": 27, "Expected": "Notes", "Found": null}, {"Expected Column Position": 28, "Expected": "Provenance", "Found": null}, {"Expected Column Position": 29, "Expected": "year", "Found": null}]}}, "exception_info": {"raised_exception": false, "exception_message": null, "exception_traceback": null}, "success": false, "meta": {}, "expectation_config": {"expectation_type": "expect_table_columns_to_match_ordered_list", "kwargs": {"column_list": ["Name", "Dates associated with name", "Type of name", "Role", "Other names", "BL record ID", "Type of resource", "Content type", "Material type", "BNB number", "Archival Resource Key", "ISBN", "Title", "Variant titles", "Series title", "Number within series", "Country of publication", "Place of publication", "Publisher", "Date of creation/publication", "Edition", "Physical description", "Dewey classification", "BL shelfmark", "Topics", "Genre", "Languages", "Notes", "Provenance", "year"], "result_format": "SUMMARY"}, "meta": {}}}, {"result": {"element_count": 44, "missing_count": 0, "missing_percent": 0.0, "unexpected_count": 29, "unexpected_percent": 65.9090909090909, "unexpected_percent_nonmissing": 65.9090909090909, "partial_unexpected_list": ["Miller, W.", "Sawyer, Charles James", "Clendening, Logan", "Amado, Gilberto", "Sawyer, Charles James", "Dyboski, Roman", "London, Southwark, Borough of Southwark, Council, Southwark Public Libraries and Museums", "Dyboski, Roman", "Straus, Ralph", "Sennewald, Charlotte", "Carrington, Norman Thomas", "Amado, Gilberto", "Dyboski, Roman", "Straus, Ralph", "Sennewald, Charlotte", "Pomeranz, Herman", "Ravold, John David", "Straus, Ralph", "Clark, Sarah Grames", "Carrington, Norman Thomas"], "partial_unexpected_index_list": [0, 2, 3, 5, 6, 7, 8, 9, 10, 11, 12, 14, 15, 16, 17, 19, 20, 22, 24, 28], "partial_unexpected_counts": [{"value": "Amado, Gilberto", "count": 3}, {"value": "Dyboski, Roman", "count": 3}, {"value": "Straus, Ralph", "count": 3}, {"value": "Bay, Jens Christian Ballalieu", "count": 2}, {"value": "Carrington, Norman Thomas", "count": 2}, {"value": "Clark, Sarah Grames", "count": 2}, {"value": "Clendening, Logan", "count": 2}, {"value": "London, Southwark, Borough of Southwark, Council, Southwark Public Libraries and Museums", "count": 2}, {"value": "Miller, W.", "count": 2}, {"value": "Ravold, John David", "count": 2}, {"value": "Sawyer, Charles James", "count": 2}, {"value": "Sennewald, Charlotte", "count": 2}, {"value": "Dexter, Walter", "count": 1}, {"value": "Pomeranz, Herman", "count": 1}]}, "exception_info": {"raised_exception": false, "exception_message": null, "exception_traceback": null}, "success": false, "meta": {}, "expectation_config": {"expectation_type": "expect_column_values_to_be_in_set", "kwargs": {"column": "Name", "value_set": ["Dickens, Charles"], "result_format": "SUMMARY"}, "meta": {}}}, {"result": {"element_count": 44, "unexpected_count": 0, "unexpected_percent": 0.0, "partial_unexpected_list": []}, "exception_info": {"raised_exception": false, "exception_message": null, "exception_traceback": null}, "success": true, "meta": {}, "expectation_config": {"expectation_type": "expect_column_values_to_not_be_null", "kwargs": {"column": "Name", "result_format": "SUMMARY"}, "meta": {}}}, {"result": {"element_count": 44, "unexpected_count": 0, "unexpected_percent": 0.0, "partial_unexpected_list": []}, "exception_info": {"raised_exception": false, "exception_message": null, "exception_traceback": null}, "success": true, "meta": {}, "expectation_config": {"expectation_type": "expect_column_values_to_not_be_null", "kwargs": {"column": "BL record ID", "result_format": "SUMMARY"}, "meta": {}}}, {"result": {"observed_value": 234224, "element_count": 44, "missing_count": 0, "missing_percent": 0.0}, "exception_info": {"raised_exception": false, "exception_message": null, "exception_traceback": null}, "success": false, "meta": {}, "expectation_config": {"expectation_type": "expect_column_min_to_be_between", "kwargs": {"column": "BL record ID", "min_value": 10000000, "result_format": "SUMMARY"}, "meta": {}}}, {"result": {}, "exception_info": {"raised_exception": true, "exception_message": "KeyError: 'BNB number'", "exception_traceback": "Traceback (most recent call last):\n  File \"/Users/rexboyce/opt/anaconda3/lib/python3.7/site-packages/pandas/core/indexes/base.py\", line 2897, in get_loc\n    return self._engine.get_loc(key)\n  File \"pandas/_libs/index.pyx\", line 107, in pandas._libs.index.IndexEngine.get_loc\n  File \"pandas/_libs/index.pyx\", line 131, in pandas._libs.index.IndexEngine.get_loc\n  File \"pandas/_libs/hashtable_class_helper.pxi\", line 1607, in pandas._libs.hashtable.PyObjectHashTable.get_item\n  File \"pandas/_libs/hashtable_class_helper.pxi\", line 1614, in pandas._libs.hashtable.PyObjectHashTable.get_item\nKeyError: 'BNB number'\n\nDuring handling of the above exception, another exception occurred:\n\nTraceback (most recent call last):\n  File \"/Users/rexboyce/opt/anaconda3/lib/python3.7/site-packages/great_expectations/data_asset/data_asset.py\", line 250, in wrapper\n    return_obj = func(self, **evaluation_args)\n  File \"/Users/rexboyce/opt/anaconda3/lib/python3.7/site-packages/great_expectations/dataset/pandas_dataset.py\", line 66, in inner_wrapper\n    series = self[column]\n  File \"/Users/rexboyce/opt/anaconda3/lib/python3.7/site-packages/pandas/core/frame.py\", line 2995, in __getitem__\n    indexer = self.columns.get_loc(key)\n  File \"/Users/rexboyce/opt/anaconda3/lib/python3.7/site-packages/pandas/core/indexes/base.py\", line 2899, in get_loc\n    return self._engine.get_loc(self._maybe_cast_indexer(key))\n  File \"pandas/_libs/index.pyx\", line 107, in pandas._libs.index.IndexEngine.get_loc\n  File \"pandas/_libs/index.pyx\", line 131, in pandas._libs.index.IndexEngine.get_loc\n  File \"pandas/_libs/hashtable_class_helper.pxi\", line 1607, in pandas._libs.hashtable.PyObjectHashTable.get_item\n  File \"pandas/_libs/hashtable_class_helper.pxi\", line 1614, in pandas._libs.hashtable.PyObjectHashTable.get_item\nKeyError: 'BNB number'\n"}, "success": false, "meta": {}, "expectation_config": {"expectation_type": "expect_column_values_to_not_be_null", "kwargs": {"column": "BNB number", "mostly": 0.85, "result_format": "SUMMARY"}, "meta": {}}}, {"result": {}, "exception_info": {"raised_exception": true, "exception_message": "KeyError: 'BNB number'", "exception_traceback": "Traceback (most recent call last):\n  File \"/Users/rexboyce/opt/anaconda3/lib/python3.7/site-packages/pandas/core/indexes/base.py\", line 2897, in get_loc\n    return self._engine.get_loc(key)\n  File \"pandas/_libs/index.pyx\", line 107, in pandas._libs.index.IndexEngine.get_loc\n  File \"pandas/_libs/index.pyx\", line 131, in pandas._libs.index.IndexEngine.get_loc\n  File \"pandas/_libs/hashtable_class_helper.pxi\", line 1607, in pandas._libs.hashtable.PyObjectHashTable.get_item\n  File \"pandas/_libs/hashtable_class_helper.pxi\", line 1614, in pandas._libs.hashtable.PyObjectHashTable.get_item\nKeyError: 'BNB number'\n\nDuring handling of the above exception, another exception occurred:\n\nTraceback (most recent call last):\n  File \"/Users/rexboyce/opt/anaconda3/lib/python3.7/site-packages/great_expectations/data_asset/data_asset.py\", line 250, in wrapper\n    return_obj = func(self, **evaluation_args)\n  File \"/Users/rexboyce/opt/anaconda3/lib/python3.7/site-packages/great_expectations/dataset/pandas_dataset.py\", line 66, in inner_wrapper\n    series = self[column]\n  File \"/Users/rexboyce/opt/anaconda3/lib/python3.7/site-packages/pandas/core/frame.py\", line 2995, in __getitem__\n    indexer = self.columns.get_loc(key)\n  File \"/Users/rexboyce/opt/anaconda3/lib/python3.7/site-packages/pandas/core/indexes/base.py\", line 2899, in get_loc\n    return self._engine.get_loc(self._maybe_cast_indexer(key))\n  File \"pandas/_libs/index.pyx\", line 107, in pandas._libs.index.IndexEngine.get_loc\n  File \"pandas/_libs/index.pyx\", line 131, in pandas._libs.index.IndexEngine.get_loc\n  File \"pandas/_libs/hashtable_class_helper.pxi\", line 1607, in pandas._libs.hashtable.PyObjectHashTable.get_item\n  File \"pandas/_libs/hashtable_class_helper.pxi\", line 1614, in pandas._libs.hashtable.PyObjectHashTable.get_item\nKeyError: 'BNB number'\n"}, "success": false, "meta": {}, "expectation_config": {"expectation_type": "expect_column_value_lengths_to_be_between", "kwargs": {"column": "BNB number", "min_value": 9, "result_format": "SUMMARY"}, "meta": {}}}, {"result": {}, "exception_info": {"raised_exception": true, "exception_message": "KeyError: 'ISBN'", "exception_traceback": "Traceback (most recent call last):\n  File \"/Users/rexboyce/opt/anaconda3/lib/python3.7/site-packages/pandas/core/indexes/base.py\", line 2897, in get_loc\n    return self._engine.get_loc(key)\n  File \"pandas/_libs/index.pyx\", line 107, in pandas._libs.index.IndexEngine.get_loc\n  File \"pandas/_libs/index.pyx\", line 131, in pandas._libs.index.IndexEngine.get_loc\n  File \"pandas/_libs/hashtable_class_helper.pxi\", line 1607, in pandas._libs.hashtable.PyObjectHashTable.get_item\n  File \"pandas/_libs/hashtable_class_helper.pxi\", line 1614, in pandas._libs.hashtable.PyObjectHashTable.get_item\nKeyError: 'ISBN'\n\nDuring handling of the above exception, another exception occurred:\n\nTraceback (most recent call last):\n  File \"/Users/rexboyce/opt/anaconda3/lib/python3.7/site-packages/great_expectations/data_asset/data_asset.py\", line 250, in wrapper\n    return_obj = func(self, **evaluation_args)\n  File \"/Users/rexboyce/opt/anaconda3/lib/python3.7/site-packages/great_expectations/dataset/pandas_dataset.py\", line 66, in inner_wrapper\n    series = self[column]\n  File \"/Users/rexboyce/opt/anaconda3/lib/python3.7/site-packages/pandas/core/frame.py\", line 2995, in __getitem__\n    indexer = self.columns.get_loc(key)\n  File \"/Users/rexboyce/opt/anaconda3/lib/python3.7/site-packages/pandas/core/indexes/base.py\", line 2899, in get_loc\n    return self._engine.get_loc(self._maybe_cast_indexer(key))\n  File \"pandas/_libs/index.pyx\", line 107, in pandas._libs.index.IndexEngine.get_loc\n  File \"pandas/_libs/index.pyx\", line 131, in pandas._libs.index.IndexEngine.get_loc\n  File \"pandas/_libs/hashtable_class_helper.pxi\", line 1607, in pandas._libs.hashtable.PyObjectHashTable.get_item\n  File \"pandas/_libs/hashtable_class_helper.pxi\", line 1614, in pandas._libs.hashtable.PyObjectHashTable.get_item\nKeyError: 'ISBN'\n"}, "success": false, "meta": {}, "expectation_config": {"expectation_type": "expect_column_values_to_not_be_null", "kwargs": {"column": "ISBN", "mostly": 0.877, "result_format": "SUMMARY"}, "meta": {}}}, {"result": {}, "exception_info": {"raised_exception": true, "exception_message": "KeyError: 'ISBN'", "exception_traceback": "Traceback (most recent call last):\n  File \"/Users/rexboyce/opt/anaconda3/lib/python3.7/site-packages/pandas/core/indexes/base.py\", line 2897, in get_loc\n    return self._engine.get_loc(key)\n  File \"pandas/_libs/index.pyx\", line 107, in pandas._libs.index.IndexEngine.get_loc\n  File \"pandas/_libs/index.pyx\", line 131, in pandas._libs.index.IndexEngine.get_loc\n  File \"pandas/_libs/hashtable_class_helper.pxi\", line 1607, in pandas._libs.hashtable.PyObjectHashTable.get_item\n  File \"pandas/_libs/hashtable_class_helper.pxi\", line 1614, in pandas._libs.hashtable.PyObjectHashTable.get_item\nKeyError: 'ISBN'\n\nDuring handling of the above exception, another exception occurred:\n\nTraceback (most recent call last):\n  File \"/Users/rexboyce/opt/anaconda3/lib/python3.7/site-packages/great_expectations/data_asset/data_asset.py\", line 250, in wrapper\n    return_obj = func(self, **evaluation_args)\n  File \"/Users/rexboyce/opt/anaconda3/lib/python3.7/site-packages/great_expectations/dataset/pandas_dataset.py\", line 66, in inner_wrapper\n    series = self[column]\n  File \"/Users/rexboyce/opt/anaconda3/lib/python3.7/site-packages/pandas/core/frame.py\", line 2995, in __getitem__\n    indexer = self.columns.get_loc(key)\n  File \"/Users/rexboyce/opt/anaconda3/lib/python3.7/site-packages/pandas/core/indexes/base.py\", line 2899, in get_loc\n    return self._engine.get_loc(self._maybe_cast_indexer(key))\n  File \"pandas/_libs/index.pyx\", line 107, in pandas._libs.index.IndexEngine.get_loc\n  File \"pandas/_libs/index.pyx\", line 131, in pandas._libs.index.IndexEngine.get_loc\n  File \"pandas/_libs/hashtable_class_helper.pxi\", line 1607, in pandas._libs.hashtable.PyObjectHashTable.get_item\n  File \"pandas/_libs/hashtable_class_helper.pxi\", line 1614, in pandas._libs.hashtable.PyObjectHashTable.get_item\nKeyError: 'ISBN'\n"}, "success": false, "meta": {}, "expectation_config": {"expectation_type": "expect_column_value_lengths_to_be_between", "kwargs": {"column": "ISBN", "min_value": 13, "result_format": "SUMMARY"}, "meta": {}}}, {"result": {}, "exception_info": {"raised_exception": true, "exception_message": "KeyError: 'Dewey classification'", "exception_traceback": "Traceback (most recent call last):\n  File \"/Users/rexboyce/opt/anaconda3/lib/python3.7/site-packages/pandas/core/indexes/base.py\", line 2897, in get_loc\n    return self._engine.get_loc(key)\n  File \"pandas/_libs/index.pyx\", line 107, in pandas._libs.index.IndexEngine.get_loc\n  File \"pandas/_libs/index.pyx\", line 131, in pandas._libs.index.IndexEngine.get_loc\n  File \"pandas/_libs/hashtable_class_helper.pxi\", line 1607, in pandas._libs.hashtable.PyObjectHashTable.get_item\n  File \"pandas/_libs/hashtable_class_helper.pxi\", line 1614, in pandas._libs.hashtable.PyObjectHashTable.get_item\nKeyError: 'Dewey classification'\n\nDuring handling of the above exception, another exception occurred:\n\nTraceback (most recent call last):\n  File \"/Users/rexboyce/opt/anaconda3/lib/python3.7/site-packages/great_expectations/data_asset/data_asset.py\", line 250, in wrapper\n    return_obj = func(self, **evaluation_args)\n  File \"/Users/rexboyce/opt/anaconda3/lib/python3.7/site-packages/great_expectations/dataset/pandas_dataset.py\", line 66, in inner_wrapper\n    series = self[column]\n  File \"/Users/rexboyce/opt/anaconda3/lib/python3.7/site-packages/pandas/core/frame.py\", line 2995, in __getitem__\n    indexer = self.columns.get_loc(key)\n  File \"/Users/rexboyce/opt/anaconda3/lib/python3.7/site-packages/pandas/core/indexes/base.py\", line 2899, in get_loc\n    return self._engine.get_loc(self._maybe_cast_indexer(key))\n  File \"pandas/_libs/index.pyx\", line 107, in pandas._libs.index.IndexEngine.get_loc\n  File \"pandas/_libs/index.pyx\", line 131, in pandas._libs.index.IndexEngine.get_loc\n  File \"pandas/_libs/hashtable_class_helper.pxi\", line 1607, in pandas._libs.hashtable.PyObjectHashTable.get_item\n  File \"pandas/_libs/hashtable_class_helper.pxi\", line 1614, in pandas._libs.hashtable.PyObjectHashTable.get_item\nKeyError: 'Dewey classification'\n"}, "success": false, "meta": {}, "expectation_config": {"expectation_type": "expect_column_values_to_not_be_null", "kwargs": {"column": "Dewey classification", "mostly": 0.85, "result_format": "SUMMARY"}, "meta": {}}}, {"result": {}, "exception_info": {"raised_exception": true, "exception_message": "KeyError: 'Dewey classification'", "exception_traceback": "Traceback (most recent call last):\n  File \"/Users/rexboyce/opt/anaconda3/lib/python3.7/site-packages/pandas/core/indexes/base.py\", line 2897, in get_loc\n    return self._engine.get_loc(key)\n  File \"pandas/_libs/index.pyx\", line 107, in pandas._libs.index.IndexEngine.get_loc\n  File \"pandas/_libs/index.pyx\", line 131, in pandas._libs.index.IndexEngine.get_loc\n  File \"pandas/_libs/hashtable_class_helper.pxi\", line 1607, in pandas._libs.hashtable.PyObjectHashTable.get_item\n  File \"pandas/_libs/hashtable_class_helper.pxi\", line 1614, in pandas._libs.hashtable.PyObjectHashTable.get_item\nKeyError: 'Dewey classification'\n\nDuring handling of the above exception, another exception occurred:\n\nTraceback (most recent call last):\n  File \"/Users/rexboyce/opt/anaconda3/lib/python3.7/site-packages/great_expectations/data_asset/data_asset.py\", line 250, in wrapper\n    return_obj = func(self, **evaluation_args)\n  File \"/Users/rexboyce/opt/anaconda3/lib/python3.7/site-packages/great_expectations/dataset/pandas_dataset.py\", line 66, in inner_wrapper\n    series = self[column]\n  File \"/Users/rexboyce/opt/anaconda3/lib/python3.7/site-packages/pandas/core/frame.py\", line 2995, in __getitem__\n    indexer = self.columns.get_loc(key)\n  File \"/Users/rexboyce/opt/anaconda3/lib/python3.7/site-packages/pandas/core/indexes/base.py\", line 2899, in get_loc\n    return self._engine.get_loc(self._maybe_cast_indexer(key))\n  File \"pandas/_libs/index.pyx\", line 107, in pandas._libs.index.IndexEngine.get_loc\n  File \"pandas/_libs/index.pyx\", line 131, in pandas._libs.index.IndexEngine.get_loc\n  File \"pandas/_libs/hashtable_class_helper.pxi\", line 1607, in pandas._libs.hashtable.PyObjectHashTable.get_item\n  File \"pandas/_libs/hashtable_class_helper.pxi\", line 1614, in pandas._libs.hashtable.PyObjectHashTable.get_item\nKeyError: 'Dewey classification'\n"}, "success": false, "meta": {}, "expectation_config": {"expectation_type": "expect_column_values_to_be_between", "kwargs": {"column": "Dewey classification", "max_value": 1000, "min_value": 0, "result_format": "SUMMARY"}, "meta": {}}}, {"result": {}, "exception_info": {"raised_exception": true, "exception_message": "KeyError: 'Genre'", "exception_traceback": "Traceback (most recent call last):\n  File \"/Users/rexboyce/opt/anaconda3/lib/python3.7/site-packages/pandas/core/indexes/base.py\", line 2897, in get_loc\n    return self._engine.get_loc(key)\n  File \"pandas/_libs/index.pyx\", line 107, in pandas._libs.index.IndexEngine.get_loc\n  File \"pandas/_libs/index.pyx\", line 131, in pandas._libs.index.IndexEngine.get_loc\n  File \"pandas/_libs/hashtable_class_helper.pxi\", line 1607, in pandas._libs.hashtable.PyObjectHashTable.get_item\n  File \"pandas/_libs/hashtable_class_helper.pxi\", line 1614, in pandas._libs.hashtable.PyObjectHashTable.get_item\nKeyError: 'Genre'\n\nDuring handling of the above exception, another exception occurred:\n\nTraceback (most recent call last):\n  File \"/Users/rexboyce/opt/anaconda3/lib/python3.7/site-packages/great_expectations/data_asset/data_asset.py\", line 250, in wrapper\n    return_obj = func(self, **evaluation_args)\n  File \"/Users/rexboyce/opt/anaconda3/lib/python3.7/site-packages/great_expectations/dataset/pandas_dataset.py\", line 66, in inner_wrapper\n    series = self[column]\n  File \"/Users/rexboyce/opt/anaconda3/lib/python3.7/site-packages/pandas/core/frame.py\", line 2995, in __getitem__\n    indexer = self.columns.get_loc(key)\n  File \"/Users/rexboyce/opt/anaconda3/lib/python3.7/site-packages/pandas/core/indexes/base.py\", line 2899, in get_loc\n    return self._engine.get_loc(self._maybe_cast_indexer(key))\n  File \"pandas/_libs/index.pyx\", line 107, in pandas._libs.index.IndexEngine.get_loc\n  File \"pandas/_libs/index.pyx\", line 131, in pandas._libs.index.IndexEngine.get_loc\n  File \"pandas/_libs/hashtable_class_helper.pxi\", line 1607, in pandas._libs.hashtable.PyObjectHashTable.get_item\n  File \"pandas/_libs/hashtable_class_helper.pxi\", line 1614, in pandas._libs.hashtable.PyObjectHashTable.get_item\nKeyError: 'Genre'\n"}, "success": false, "meta": {}, "expectation_config": {"expectation_type": "expect_column_values_to_not_be_null", "kwargs": {"column": "Genre", "mostly": 0.59, "result_format": "SUMMARY"}, "meta": {}}}], "success": false, "evaluation_parameters": {}, "meta": {"great_expectations.__version__": "0.11.2", "expectation_suite_name": "dickens_trends", "run_id": {"run_name": "20200715T200141.990336Z", "run_time": "2020-07-15T20:01:41.990336+00:00"}, "batch_kwargs": {"datasource": "annual__dir", "path": "annual/dickens_research_data_1936.csv"}, "batch_markers": {"ge_load_time": "20200715T200141.978730Z", "pandas_data_fingerprint": "7bd44cc62c0e651274dc5ea80b4babd8"}, "batch_parameters": null, "validation_time": "20200715T200141.990539Z"}}